---
title: "07_例外処理"
---

articlesにある「例外処理」の熟読の上、下記の問題の回答をお願いいたします。

* 回答記載方法
IntelliJ IDEAにて、Javaリポジトリをクローンし、`src/curriculum7` ディレクトリ配下に各問題ごとでJavaクラスを作成「Question1、Question2...」して、そこに回答を記載してください。
なお、プログラミングを書かない回答(選択問題等)に関しては、print関数を用いて回答を出力するコードを記載ください。

* 回答提出方法
Javaリポジトリに対して、回答者がわかる名称でbranchを切り、pushをお願いします。
push後は、「Java」チャットでトレーナーに回答した旨をお伝えください。

* 質問方法
質問用のSlack「java_質問」チャンネルでトレーナーをメンションにつけてご質問ください。
なお、質問や疑問点の内容は必ず複数人が閲覧できるようにしておきたい為、受講者からトレーナーへのDM（ダイレクトメッセージ）による質問は原則禁止とします。
なお、合格ラインは全問正解となり、回答のフィードバックや質問等は各自トレーナーとやり取りをお願いいたします。

## 問題

### 問題1
次のコードを実行すると、どのような例外が発生しますか？

```java
public class Main {
    public static void main(String[] args) {
        int[] numbers = {1, 2, 3};
        System.out.println(numbers[3]);
    }
}
```

### 問題2
次のコードで`catch`ブロックが実行される場合、出力はどうなりますか？

```java
public class Main {
    public static void main(String[] args) {
        try {
            int result = 10 / 0;
        } catch (ArithmeticException e) {
            System.out.println("エラーが発生しました: " + e.getMessage());
        }
    }
}
```

### 問題3
`try-catch`文を使って、次のコードが例外を処理するように変更してください。もし例外が発生したら「例外が発生しました」と表示してください。

```java
public class Main {
    public static void main(String[] args) {
        String text = null;
        System.out.println(text.length());
    }
}
```

### 問題4
次のコードは、どの部分で例外が発生し、どの`catch`ブロックが実行されますか？

```java
public class Main {
    public static void main(String[] args) {
        try {
            int[] array = new int[5];
            array[5] = 10;
        } catch (ArithmeticException e) {
            System.out.println("算術エラーが発生しました。");
        } catch (ArrayIndexOutOfBoundsException e) {
            System.out.println("配列のインデックスが範囲外です。");
        }
    }
}
```

### 問題5
次のコードを実行すると、`finally`ブロックは実行されますか？

```java
public class Main {
    public static void main(String[] args) {
        try {
            int result = 10 / 0;
        } catch (ArithmeticException e) {
            System.out.println("エラーが発生しました: " + e.getMessage());
        } finally {
            System.out.println("このメッセージは必ず表示されます。");
        }
    }
}

```

### 問題6
`try-catch-finally`構文を使用して、次のコードを例外処理するように変更してください。例外が発生した場合、「エラーが発生しました」と表示し、最後に「プログラム終了」を必ず表示してください。

```java
public class Main {
    public static void main(String[] args) {
        int result = 10 / 0;
        System.out.println("結果: " + result);
    }
}
```

### 問題7
`throw`キーワードを使用して、自分で例外を発生させるコードを記述してください。例外は`IllegalArgumentException`を使用し、メッセージとして「不正な引数です」を指定してください。

### 問題8
次のコードでは、どの例外クラスをキャッチするべきですか？

```java
public class Main {
    public static void main(String[] args) {
        String[] fruits = {"Apple", "Banana", "Orange"};
        System.out.println(fruits[3]);
    }
}
```

### 問題9
複数の例外が発生する可能性のあるコードを書き、その例外を個別にキャッチして適切に処理するプログラムを記述してください。例として、配列の範囲外と`null`値の例外を処理します。

### 問題10
カスタム例外を作成し、それを`try-catch`でキャッチするプログラムを記述してください。カスタム例外クラス名は`MyCustomException`とします。

